<?xml version="1.0"?>
<robot name="simple_arm">
  
  <!-- Base Link -->
  <link name="base_link">
    <visual>
      <origin xyz="0 0 0.05" rpy="0 0 0"/>
      <geometry>
        <cylinder length="0.1" radius="0.15"/>
      </geometry>
      <material name="gray">
        <color rgba="0.5 0.5 0.5 1.0"/>
      </material>
    </visual>
  </link>
  
  <!-- Link 1 - Rotating base -->
  <link name="link1">
    <visual>
      <origin xyz="0 0 0.075" rpy="0 0 0"/>
      <geometry>
        <cylinder length="0.15" radius="0.1"/>
      </geometry>
      <material name="metallic_blue">
        <color rgba="0.2 0.3 0.8 1.0"/>
      </material>
    </visual>
  </link>
  
  <!-- Link 2 - Upper arm -->
  <link name="link2">
    <visual>
      <origin xyz="0.2 0 0" rpy="0 1.5708 0"/>
      <geometry>
        <cylinder length="0.4" radius="0.06"/>
      </geometry>
      <material name="red">
        <color rgba="1.0 0.0 0.0 1.0"/>
      </material>
    </visual>
  </link>
  
  <!-- Link 3 - Forearm -->
  <link name="link3">
    <visual>
      <origin xyz="0.15 0 0" rpy="0 1.5708 0"/>
      <geometry>
        <cylinder length="0.3" radius="0.05"/>
      </geometry>
      <material name="green">
        <color rgba="0.0 1.0 0.0 1.0"/>
      </material>
    </visual>
  </link>
  
  <!-- Link 4 - Wrist 1 -->
  <link name="link4">
    <visual>
      <origin xyz="0 0 0.05" rpy="0 0 0"/>
      <geometry>
        <cylinder length="0.1" radius="0.04"/>
      </geometry>
      <material name="yellow">
        <color rgba="1.0 1.0 0.0 1.0"/>
      </material>
    </visual>
  </link>
  
  <!-- Link 5 - Wrist 2 -->
  <link name="link5">
    <visual>
      <origin xyz="0 0.05 0" rpy="1.5708 0 0"/>
      <geometry>
        <cylinder length="0.1" radius="0.04"/>
      </geometry>
      <material name="orange">
        <color rgba="1.0 0.5 0.0 1.0"/>
      </material>
    </visual>
  </link>
  
  <!-- Link 6 - End effector -->
  <link name="link6">
    <visual>
      <origin xyz="0 0 0.03" rpy="0 0 0"/>
      <geometry>
        <sphere radius="0.05"/>
      </geometry>
      <material name="gold">
        <color rgba="1.0 0.843 0.0 1.0"/>
      </material>
    </visual>
    <visual>
      <origin xyz="0 0 0.08" rpy="0 0 0"/>
      <geometry>
        <cylinder length="0.08" radius="0.03"/>
      </geometry>
      <material name="purple">
        <color rgba="0.5 0.0 0.5 1.0"/>
      </material>
    </visual>
  </link>
  
  <!-- Joints -->
  
  <!-- Base Joint -->
  <joint name="base_joint" type="revolute">
    <parent link="base_link"/>
    <child link="link1"/>
    <origin xyz="0 0 0.1" rpy="0 0 0"/>
    <axis xyz="0 0 1"/>
    <limit lower="-3.14159" upper="3.14159" effort="100" velocity="1.0"/>
  </joint>
  
  <!-- Shoulder Joint -->
  <joint name="shoulder_joint" type="revolute">
    <parent link="link1"/>
    <child link="link2"/>
    <origin xyz="0 0 0.15" rpy="0 0 0"/>
    <axis xyz="0 1 0"/>
    <limit lower="-1.5708" upper="1.5708" effort="100" velocity="1.0"/>
  </joint>
  
  <!-- Elbow Joint -->
  <joint name="elbow_joint" type="revolute">
    <parent link="link2"/>
    <child link="link3"/>
    <origin xyz="0.4 0 0" rpy="0 0 0"/>
    <axis xyz="0 1 0"/>
    <limit lower="-2.0" upper="2.0" effort="100" velocity="1.0"/>
  </joint>
  
  <!-- Wrist 1 Joint -->
  <joint name="wrist_1_joint" type="revolute">
    <parent link="link3"/>
    <child link="link4"/>
    <origin xyz="0.3 0 0" rpy="0 0 0"/>
    <axis xyz="0 1 0"/>
    <limit lower="-2.0" upper="2.0" effort="100" velocity="1.0"/>
  </joint>
  
  <!-- Wrist 2 Joint -->
  <joint name="wrist_2_joint" type="revolute">
    <parent link="link4"/>
    <child link="link5"/>
    <origin xyz="0 0 0.1" rpy="0 0 0"/>
    <axis xyz="0 0 1"/>
    <limit lower="-3.14159" upper="3.14159" effort="100" velocity="1.0"/>
  </joint>
  
  <!-- Wrist 3 Joint -->
  <joint name="wrist_3_joint" type="revolute">
    <parent link="link5"/>
    <child link="link6"/>
    <origin xyz="0 0.1 0" rpy="0 0 0"/>
    <axis xyz="1 0 0"/>
    <limit lower="-3.14159" upper="3.14159" effort="100" velocity="1.0"/>
  </joint>
  
</robot>